Workbook

Sheet README
B2: Signal Array — Financial Model
B3: Three-year monthly projections · base / conservative / optimistic / downside scenarios
B5: About this model
B6: This workbook models Signal Array's commercial trajectory from May 2026 through April 2029 (Y1 = FY27, Y2 = FY28, Y3 = FY29).
B7: Inputs live in the Assumptions sheet (blue cells). Change them to flex scenarios.
B9: Color conventions (industry standard):
B10: BLUE text = hardcoded inputs you can change
B11: BLACK text = formulas
B12: GREEN text = cross-sheet links
B13: YELLOW background = key assumptions warranting attention
B15: Sheets:
B16: 1. README — this overview
... B27: Companion document: Signal Array — Business Plan.md (in the same /assets folder)

Sheet Assumptions
A1: Signal Array — Key Assumptions
A3: PRICING (base case)
A4: Moloco engagement (Year 1, annualized) | B4: 150000 | C4: Existing design-contract terms; assumed extension
A5: Moloco engagement (Year 2) | B5: 200000 | C5: Extension assumption — refines based on Phase 3 outcome
A6: Moloco engagement (Year 3) | B6: 350000 | C6: Expanded scope assumption
A7: Pilot Pack — one-time fee | B7: 30000 | C7: Custom vertical pack + 1 calibration case study
A8: Pilot Pack — annual hosted access (Y1) | B8: 15000 | C8: First year hosted access
A9: Pilot Pack — renewal (Y2+) | B9: 25000 | C9: Bumps up after value demonstrated
A10: Platform tier — annual license | B10: 40000 | C10: All-pack access + white-glove pack authoring
A11: Platform tier — pack authoring (one-time, per pack) | B11: 60000 | C11: Custom pack content for the customer
A12: Enterprise tier — annual ACV (estimated) | B12: 250000 | C12: Custom; assume mid-range for projections
A13: Creative Portfolios public demo | B13: 0 | C13: Free; top-of-funnel acquisition channel
A15: CUSTOMER ACQUISITION (base case)
A16: New Pilot Pack customers — Year 1 | B16: 2 | C16: Beyond Moloco; 2 new in Y1
A17: New Pilot Pack customers — Year 2 | B17: 4 | C17: Four new Pilot Packs across Y2
A18: New Pilot Pack customers — Year 3 | B18: 5 | C18: Steady inflow at Pilot tier
A19: Pilot-to-Platform conversion rate | B19: 0.5 | C19: Half of Pilot customers upgrade to Platform after 12 months
A20: New Platform customers — Year 2 | B20: 2 | C20: Initial Platform signups in Y2
A21: New Platform customers — Year 3 | B21: 6 | C21: Direct + upgrades
A22: New Enterprise customers — Year 3 | B22: 2 | C22: Begin in Y3 once SOC 2 evidence is available
A23: Average sales cycle (months) — Pilot | B23: 2 | C23: Inbound + warm intro; short cycle
A24: Average sales cycle (months) — Platform | B24: 4 | C24: Procurement + legal review
A25: Average sales cycle (months) — Enterprise | B25: 6 | C25: Compliance review, multi-stakeholder
A26: Annual customer churn rate | B26: 0.1 | C26: Conservative; calibration-trust moat lowers churn
A28: COST PARAMETERS
A29: LLM cost per cohort run (avg) | B29: 10 | C29: Claude Opus + Sonnet mix; ~$5-15 range
A30: Cohort runs per customer per month (avg) | B30: 30 | C30: Scales with customer engagement
A31: Hosting cost per customer per month | B31: 50 | C31: Vercel + Neon + R2 + Inngest
A32: Tooling cost monthly (fixed) | B32: 400 | C32: Stripe, Clerk, Sentry, PostHog, Resend
A33: Legal — Year 1 | B33: 15000 | C33: Entity, contracts, trademark filing
A34: Legal — Year 2 | B34: 25000 | C34: Customer contracts, SOC 2 prep
A35: Legal — Year 3 | B35: 40000 | C35: Scale-up
A36: Accounting/tax annual | B36: 6000 | C36: Bookkeeping + tax prep
A37: Marketing — Year 1 | B37: 5000 | C37: Conference travel; minimal
A38: Marketing — Year 2 | B38: 30000 | C38: Content production + paid acquisition tests
A39: Marketing — Year 3 | B39: 150000 | C39: Full GTM motion
A40: Engineer contractor monthly (Y2 start) | B40: 8000 | C40: Part-time; ~10-20 hrs/week loaded
... A47: Shalom comp Y3 | B47: 200000 | C47: Full-time-equivalent founder compensation
A49: SCENARIO MULTIPLIERS
A50: Active scenario (1=base, 2=conservative, 3=optimistic, 4=downside) | B50: 1 | C50: Change this single cell to flex the entire model
...

Sheet Revenue
A1: Signal Array — Revenue Projection
B2: Year 1 (May26-Apr27) | N2: Year 2 (May27-Apr28) | Z2: Year 3 (May28-Apr29) | AL2: Y1 Total | AM2: Y2 Total | AN2: Y3 Total | AO2: 3Y Total
A3: Month | B3: May-26 | C3: Jun-26 | D3: Jul-26 | E3: Aug-26 | F3: Sep-26 | G3: Oct-26 | H3: Nov-26 | I3: Dec-26 | J3: Jan-27 | K3: Feb-27 | L3: Mar-27 | M3: Apr-27 | N3: May-27 | O3: Jun-27 | P3: Jul-27 | Q3: Aug-27 | R3: Sep-27 | S3: Oct-27 | T3: Nov-27 | U3: Dec-27 | V3: Jan-28 | W3: Feb-28 | X3: Mar-28 | Y3: Apr-28 | Z3: May-28 | AA3: Jun-28 | AB3: Jul-28 | AC3: Aug-28 | AD3: Sep-28 | AE3: Oct-28 | AF3: Nov-28 | AG3: Dec-28 | AH3: Jan-29 | AI3: Feb-29 | AJ3: Mar-29 | AK3: Apr-29
A5: CUSTOMER COUNTS (active, end of month)
A6: Moloco (lighthouse customer) | B6: 1 | C6: 1 | D6: 1 | E6: 1 | F6: 1 | G6: 1 | H6: 1 | I6: 1 | J6: 1 | K6: 1 | L6: 1 | M6: 1 | N6: 1 | O6: 1 | P6: 1 | Q6: 1 | R6: 1 | S6: 1 | T6: 1 | U6: 1 | V6: 1 | W6: 1 | X6: 1 | Y6: 1 | Z6: 1 | AA6: 1 | AB6: 1 | AC6: 1 | AD6: 1 | AE6: 1 | AF6: 1 | AG6: 1 | AH6: 1 | AI6: 1 | AJ6: 1 | AK6: 1
A7: Pilot Pack customers | B7: 0 | C7: 0 | D7: 0 | E7: 0 | F7: 0 | G7: 1 | H7: 1 | I7: 1 | J7: 1 | K7: 1 | L7: 2 | M7: 2 | N7: 2 | O7: 3 | P7: 3 | Q7: 3 | R7: 4 | S7: 4 | T7: 4 | U7: 5 | V7: 5 | W7: 5 | X7: 6 | Y7: 6 | Z7: 6 | AA7: 7 | AB7: 7 | AC7: 8 | AD7: 8 | AE7: 9 | AF7: 9 | AG7: 10 | AH7: 10 | AI7: 11 | AJ7: 11 | AK7: 11
A8: Platform tier customers | B8: 0 | C8: 0 | D8: 0 | E8: 0 | F8: 0 | G8: 0 | H8: 0 | I8: 0 | J8: 0 | K8: 0 | L8: 0 | M8: 0 | N8: 0 | O8: 0 | P8: 0 | Q8: 0 | R8: 0 | S8: 1 | T8: 1 | U8: 1 | V8: 1 | W8: 2 | X8: 2 | Y8: 2 | Z8: 3 | AA8: 3 | AB8: 4 | AC8: 4 | AD8: 5 | AE8: 5 | AF8: 6 | AG8: 6 | AH8: 7 | AI8: 7 | AJ8: 8 | AK8: 8
A9: Enterprise customers | B9: 0 | C9: 0 | D9: 0 | E9: 0 | F9: 0 | G9: 0 | H9: 0 | I9: 0 | J9: 0 | K9: 0 | L9: 0 | M9: 0 | N9: 0 | O9: 0 | P9: 0 | Q9: 0 | R9: 0 | S9: 0 | T9: 0 | U9: 0 | V9: 0 | W9: 0 | X9: 0 | Y9: 0 | Z9: 0 | AA9: 0 | AB9: 0 | AC9: 1 | AD9: 1 | AE9: 1 | AF9: 1 | AG9: 1 | AH9: 1 | AI9: 2 | AJ9: 2 | AK9: 2
A10: Total active customers | B10: =SUM(B6:B9) -> 1 | C10: =SUM(C6:C9) -> 1 | D10: =SUM(D6:D9) -> 1 | E10: =SUM(E6:E9) -> 1 | F10: =SUM(F6:F9) -> 1 | G10: =SUM(G6:G9) -> 2 | H10: =SUM(H6:H9) -> 2 | I10: =SUM(I6:I9) -> 2 | ... AK10: =SUM(AK6:AK9) -> 22
A12: MONTHLY REVENUE BY LINE ITEM ($)
A13: Moloco engagement | B13: =Assumptions!B4/12*Assumptions!B58 -> 12500 | C13: =Assumptions!B4/12*Assumptions!B58 -> 12500 | D13: =Assumptions!B4/12*Assumptions!B58 -> 12500 | E13: =Assumptions!B4/12*Assumptions!B58 -> 12500 | F13: =Assumptions!B4/12*Assumptions!B58 -> 12500 | G13: =Assumptions!B4/12*Assumptions!B58 -> 12500 | H13: =Assumptions!B4/12*Assumptions!B58 -> 12500 | I13: =Assumptions!B4/12*Assumptions!B58 -> 12500 | J13: =Assumptions!B4/12*Assumptions!B58 -> 12500 | K13: =Assumptions!B4/12*Assumptions!B58 -> 12500 | L13: =Assumptions!B4/12*Assumptions!B58 -> 12500 | M13: =Assumptions!B4/12*Assumptions!B58 -> 12500 | N13: =Assumptions!B5/12*Assumptions!B58 -> 16666.667 | O13: =Assumptions!B5/12*Assumptions!B58 -> 16666.667 | P13: =Assumptions!B5/12*Assumptions!B58 -> 16666.667 | Q13: =Assumptions!B5/12*Assumptions!B58 -> 16666.667 | R13: =Assumptions!B5/12*Assumptions!B58 -> 16666.667 | S13: =Assumptions!B5/12*Assumptions!B58 -> 16666.667 | T13: =Assumptions!B5/12*Assumptions!B58 -> 16666.667 | U13: =Assumptions!B5/12*Assumptions!B58 -> 16666.667 | V13: =Assumptions!B5/12*Assumptions!B58 -> 16666.667 | W13: =Assumptions!B5/12*Assumptions!B58 -> 16666.667 | X13: =Assumptions!B5/12*Assumptions!B58 -> 16666.667 | Y13: =Assumptions!B5/12*Assumptions!B58 -> 16666.667 | Z13: =Assumptions!B6/12*Assumptions!B58 -> 29166.667 | AA13: =Assumptions!B6/12*Assumptions!B58 -> 29166.667 | AB13: =Assumptions!B6/12*Assumptions!B58 -> 29166.667 | AC13: =Assumptions!B6/12*Assumptions!B58 -> 29166.667 | AD13: =Assumptions!B6/12*Assumptions!B58 -> 29166.667 | AE13: =Assumptions!B6/12*Assumptions!B58 -> 29166.667 | AF13: =Assumptions!B6/12*Assumptions!B58 -> 29166.667 | AG13: =Assumptions!B6/12*Assumptions!B58 -> 29166.667 | AH13: =Assumptions!B6/12*Assumptions!B58 -> 29166.667 | AI13: =Assumptions!B6/12*Assumptions!B58 -> 29166.667 | AJ13: =Assumptions!B6/12*Assumptions!B58 -> 29166.667 | AK13: =Assumptions!B6/12*Assumptions!B58 -> 29166.667 | AL13: =SUM(B13:M13) -> 150000 | AM13: =SUM(N13:Y13) -> 200000 | AN13: =SUM(Z13:AK13) -> 350000 | AO13: =AL13+AM13+AN13 -> 700000
A14: Pilot Pack — one-time fees | B14: 0 | C14: 0 | D14: 0 | E14: 0 | F14: 0 | G14: =1*Assumptions!B7*Assumptions!B58 -> 30000 | H14: 0 | I14: 0 | J14: 0 | K14: 0 | L14: =1*Assumptions!B7*Assumptions!B58 -> 30000 | M14: 0 | N14: 0 | O14: =1*Assumptions!B7*Assumptions!B58 -> 30000 | P14: 0 | Q14: 0 | R14: =1*Assumptions!B7*Assumptions!B58 -> 30000 | S14: 0 | T14: 0 | U14: =1*Assumptions!B7*Assumptions!B58 -> 30000 | V14: 0 | W14: 0 | X14: =1*Assumptions!B7*Assumptions!B58 -> 30000 | Y14: 0 | Z14: 0 | AA14: =1*Assumptions!B7*Assumptions!B58 -> 30000 | AB14: 0 | AC14: =1*Assumptions!B7*Assumptions!B58 -> 30000 | AD14: 0 | AE14: =1*Assumptions!B7*Assumptions!B58 -> 30000 | AF14: 0 | AG14: =1*Assumptions!B7*Assumptions!B58 -> 30000 | AH14: 0 | AI14: =1*Assumptions!B7*Assumptions!B58 -> 30000 | AJ14: 0 | AK14: 0 | AL14: =SUM(B14:M14) -> 60000 | AM14: =SUM(N14:Y14) -> 120000 | AN14: =SUM(Z14:AK14) -> 150000 | AO14: =AL14+AM14+AN14 -> 330000
A15: Pilot Pack — recurring hosting | B15: =B7*Assumptions!B8/12*Assumptions!B58 -> 0 | C15: =C7*Assumptions!B8/12*Assumptions!B58 -> 0 | D15: =D7*Assumptions!B8/12*Assumptions!B58 -> 0 | E15: =E7*Assumptions!B8/12*Assumptions!B58 -> 0 | F15: =F7*Assumptions!B8/12*Assumptions!B58 -> 0 | G15: =G7*Assumptions!B8/12*Assumptions!B58 -> 1250 | H15: =H7*Assumptions!B8/12*Assumptions!B58 -> 1250 | I15: =I7*Assumptions!B8/12*Assumptions!B58 -> 1250 | J15: =J7*Assumptions!B8/12*Assumptions!B58 -> 1250 | K15: =K7*Assumptions!B8/12*Assumptions!B58 -> 1250 | L15: =L7*Assumptions!B8/12*Assumptions!B58 -> 2500 | M15: =M7*Assumptions!B8/12*Assumptions!B58 -> 2500 | N15: =N7*Assumptions!B9/12*Assumptions!B58 -> 4166.6667 | O15: =O7*Assumptions!B9/12*Assumptions!B58 -> 6250 | P15: =P7*Assumptions!B9/12*Assumptions!B58 -> 6250 | Q15: =Q7*Assumptions!B9/12*Assumptions!B58 -> 6250 | R15: =R7*Assumptions!B9/12*Assumptions!B58 -> 8333.3333 | S15: =S7*Assumptions!B9/12*Assumptions!B58 -> 8333.3333 | T15: =T7*Assumptions!B9/12*Assumptions!B58 -> 8333.3333 | U15: =U7*Assumptions!B9/12*Assumptions!B58 -> 10416.667 | V15: =V7*Assumptions!B9/12*Assumptions!B58 -> 10416.667 | W15: =W7*Assumptions!B9/12*Assumptions!B58 -> 10416.667 | X15: =X7*Assumptions!B9/12*Assumptions!B58 -> 12500 | Y15: =Y7*Assumptions!B9/12*Assumptions!B58 -> 12500 | Z15: =Z7*Assumptions!B9/12*Assumptions!B58 -> 12500 | AA15: =AA7*Assumptions!B9/12*Assumptions!B58 -> 14583.333 | AB15: =AB7*Assumptions!B9/12*Assumptions!B58 -> 14583.333 | AC15: =AC7*Assumptions!B9/12*Assumptions!B58 -> 16666.667 | AD15: =AD7*Assumptions!B9/12*Assumptions!B58 -> 16666.667 | AE15: =AE7*Assumptions!B9/12*Assumptions!B58 -> 18750 | AF15: =AF7*Assumptions!B9/12*Assumptions!B58 -> 18750 | AG15: =AG7*Assumptions!B9/12*Assumptions!B58 -> 20833.333 | AH15: =AH7*Assumptions!B9/12*Assumptions!B58 -> 20833.333 | AI15: =AI7*Assumptions!B9/12*Assumptions!B58 -> 22916.667 | AJ15: =AJ7*Assumptions!B9/12*Assumptions!B58 -> 22916.667 | AK15: =AK7*Assumptions!B9/12*Assumptions!B58 -> 22916.667 | AL15: =SUM(B15:M15) -> 11250 | AM15: =SUM(N15:Y15) -> 104166.67 | AN15: =SUM(Z15:AK15) -> 222916.67 | AO15: =AL15+AM15+AN15 -> 338333.33
A16: Platform tier — license (recurring) | B16: =B8*Assumptions!B10/12*Assumptions!B58 -> 0 | C16: =C8*Assumptions!B10/12*Assumptions!B58 -> 0 | D16: =D8*Assumptions!B10/12*Assumptions!B58 -> 0 | E16: =E8*Assumptions!B10/12*Assumptions!B58 -> 0 | F16: =F8*Assumptions!B10/12*Assumptions!B58 -> 0 | G16: =G8*Assumptions!B10/12*Assumptions!B58 -> 0 | H16: =H8*Assumptions!B10/12*Assumptions!B58 -> 0 | I16: =I8*Assumptions!B10/12*Assumptions!B58 -> 0 | J16: =J8*Assumptions!B10/12*Assumptions!B58 -> 0 | K16: =K8*Assumptions!B10/12*Assumptions!B58 -> 0 | L16: =L8*Assumptions!B10/12*Assumptions!B58 -> 0 | M16: =M8*Assumptions!B10/12*Assumptions!B58 -> 0 | N16: =N8*Assumptions!B10/12*Assumptions!B58 -> 0 | O16: =O8*Assumptions!B10/12*Assumptions!B58 -> 0 | P16: =P8*Assumptions!B10/12*Assumptions!B58 -> 0 | Q16: =Q8*Assumptions!B10/12*Assumptions!B58 -> 0 | R16: =R8*Assumptions!B10/12*Assumptions!B58 -> 0 | S16: =S8*Assumptions!B10/12*Assumptions!B58 -> 3333.3333 | T16: =T8*Assumptions!B10/12*Assumptions!B58 -> 3333.3333 | U16: =U8*Assumptions!B10/12*Assumptions!B58 -> 3333.3333 | V16: =V8*Assumptions!B10/12*Assumptions!B58 -> 3333.3333 | W16: =W8*Assumptions!B10/12*Assumptions!B58 -> 6666.6667 | X16: =X8*Assumptions!B10/12*Assumptions!B58 -> 6666.6667 | Y16: =Y8*Assumptions!B10/12*Assumptions!B58 -> 6666.6667 | Z16: =Z8*Assumptions!B10/12*Assumptions!B58 -> 10000 | AA16: =AA8*Assumptions!B10/12*Assumptions!B58 -> 10000 | AB16: =AB8*Assumptions!B10/12*Assumptions!B58 -> 13333.333 | AC16: =AC8*Assumptions!B10/12*Assumptions!B58 -> 13333.333 | AD16: =AD8*Assumptions!B10/12*Assumptions!B58 -> 16666.667 | AE16: =AE8*Assumptions!B10/12*Assumptions!B58 -> 16666.667 | AF16: =AF8*Assumptions!B10/12*Assumptions!B58 -> 20000 | AG16: =AG8*Assumptions!B10/12*Assumptions!B58 -> 20000 | AH16: =AH8*Assumptions!B10/12*Assumptions!B58 -> 23333.333 | AI16: =AI8*Assumptions!B10/12*Assumptions!B58 -> 23333.333 | AJ16: =AJ8*Assumptions!B10/12*Assumptions!B58 -> 26666.667 | AK16: =AK8*Assumptions!B10/12*Assumptions!B58 -> 26666.667 | AL16: =SUM(B16:M16) -> 0 | AM16: =SUM(N16:Y16) -> 33333.333 | AN16: =SUM(Z16:AK16) -> 220000 | AO16: =AL16+AM16+AN16 -> 253333.33
A17: Platform tier — pack authoring (one-time) | B17: 0 | C17: 0 | D17: 0 | E17: 0 | F17: 0 | G17: 0 | H17: 0 | I17: 0 | J17: 0 | K17: 0 | L17: 0 | M17: 0 | N17: 0 | O17: 0 | P17: 0 | Q17: 0 | R17: 0 | S17: =1*Assumptions!B11*Assumptions!B58 -> 60000 | T17: 0 | U17: 0 | V17: 0 | W17: =1*Assumptions!B11*Assumptions!B58 -> 60000 | X17: 0 | Y17: 0 | Z17: =1*Assumptions!B11*Assumptions!B58 -> 60000 | AA17: 0 | AB17: =1*Assumptions!B11*Assumptions!B58 -> 60000 | AC17: 0 | AD17: =1*Assumptions!B11*Assumptions!B58 -> 60000 | AE17: 0 | AF17: =1*Assumptions!B11*Assumptions!B58 -> 60000 | AG17: 0 | AH17: =1*Assumptions!B11*Assumptions!B58 -> 60000 | AI17: 0 | AJ17: =1*Assumptions!B11*Assumptions!B58 -> 60000 | AK17: 0 | AL17: =SUM(B17:M17) -> 0 | AM17: =SUM(N17:Y17) -> 120000 | AN17: =SUM(Z17:AK17) -> 360000 | AO17: =AL17+AM17+AN17 -> 480000
A18: Enterprise tier — annual ACV (recurring) | B18: =B9*Assumptions!B12/12*Assumptions!B58 -> 0 | C18: =C9*Assumptions!B12/12*Assumptions!B58 -> 0 | D18: =D9*Assumptions!B12/12*Assumptions!B58 -> 0 | E18: =E9*Assumptions!B12/12*Assumptions!B58 -> 0 | F18: =F9*Assumptions!B12/12*Assumptions!B58 -> 0 | G18: =G9*Assumptions!B12/12*Assumptions!B58 -> 0 | H18: =H9*Assumptions!B12/12*Assumptions!B58 -> 0 | I18: =I9*Assumptions!B12/12*Assumptions!B58 -> 0 | J18: =J9*Assumptions!B12/12*Assumptions!B58 -> 0 | K18: =K9*Assumptions!B12/12*Assumptions!B58 -> 0 | L18: =L9*Assumptions!B12/12*Assumptions!B58 -> 0 | M18: =M9*Assumptions!B12/12*Assumptions!B58 -> 0 | N18: =N9*Assumptions!B12/12*Assumptions!B58 -> 0 | O18: =O9*Assumptions!B12/12*Assumptions!B58 -> 0 | P18: =P9*Assumptions!B12/12*Assumptions!B58 -> 0 | Q18: =Q9*Assumptions!B12/12*Assumptions!B58 -> 0 | R18: =R9*Assumptions!B12/12*Assumptions!B58 -> 0 | S18: =S9*Assumptions!B12/12*Assumptions!B58 -> 0 | T18: =T9*Assumptions!B12/12*Assumptions!B58 -> 0 | U18: =U9*Assumptions!B12/12*Assumptions!B58 -> 0 | V18: =V9*Assumptions!B12/12*Assumptions!B58 -> 0 | W18: =W9*Assumptions!B12/12*Assumptions!B58 -> 0 | X18: =X9*Assumptions!B12/12*Assumptions!B58 -> 0 | Y18: =Y9*Assumptions!B12/12*Assumptions!B58 -> 0 | Z18: =Z9*Assumptions!B12/12*Assumptions!B58 -> 0 | AA18: =AA9*Assumptions!B12/12*Assumptions!B58 -> 0 | AB18: =AB9*Assumptions!B12/12*Assumptions!B58 -> 0 | AC18: =AC9*Assumptions!B12/12*Assumptions!B58 -> 20833.333 | AD18: =AD9*Assumptions!B12/12*Assumptions!B58 -> 20833.333 | AE18: =AE9*Assumptions!B12/12*Assumptions!B58 -> 20833.333 | AF18: =AF9*Assumptions!B12/12*Assumptions!B58 -> 20833.333 | AG18: =AG9*Assumptions!B12/12*Assumptions!B58 -> 20833.333 | AH18: =AH9*Assumptions!B12/12*Assumptions!B58 -> 20833.333 | AI18: =AI9*Assumptions!B12/12*Assumptions!B58 -> 41666.667 | AJ18: =AJ9*Assumptions!B12/12*Assumptions!B58 -> 41666.667 | AK18: =AK9*Assumptions!B12/12*Assumptions!B58 -> 41666.667 | AL18: =SUM(B18:M18) -> 0 | AM18: =SUM(N18:Y18) -> 0 | AN18: =SUM(Z18:AK18) -> 250000 | AO18: =AL18+AM18+AN18 -> 250000
A19: TOTAL MONTHLY REVENUE | B19: =SUM(B13:B18) -> 12500 | C19: =SUM(C13:C18) -> 12500 | D19: =SUM(D13:D18) -> 12500 | E19: =SUM(E13:E18) -> 12500 | F19: =SUM(F13:F18) -> 12500 | G19: =SUM(G13:G18) -> 43750 | H19: =SUM(H13:H18) -> 13750 | I19: =SUM(I13:I18) -> 13750 | ... AK19: =SUM(AK13:AK18) -> 120416.67 | AL19: =SUM(B19:M19) -> 221250 | AM19: =SUM(N19:Y19) -> 577500 | AN19: =SUM(Z19:AK19) -> 1552916.7 | AO19: =AL19+AM19+AN19 -> 2351666.7

Sheet Costs
A1: Signal Array — Cost Projection
B2: Year 1 (May26-Apr27) | N2: Year 2 (May27-Apr28) | Z2: Year 3 (May28-Apr29) | AL2: Y1 Total | AM2: Y2 Total | AN2: Y3 Total | AO2: 3Y Total
A3: Month | B3: May-26 | C3: Jun-26 | D3: Jul-26 | E3: Aug-26 | F3: Sep-26 | G3: Oct-26 | H3: Nov-26 | I3: Dec-26 | J3: Jan-27 | K3: Feb-27 | L3: Mar-27 | M3: Apr-27 | N3: May-27 | O3: Jun-27 | P3: Jul-27 | Q3: Aug-27 | R3: Sep-27 | S3: Oct-27 | T3: Nov-27 | U3: Dec-27 | V3: Jan-28 | W3: Feb-28 | X3: Mar-28 | Y3: Apr-28 | Z3: May-28 | AA3: Jun-28 | AB3: Jul-28 | AC3: Aug-28 | AD3: Sep-28 | AE3: Oct-28 | AF3: Nov-28 | AG3: Dec-28 | AH3: Jan-29 | AI3: Feb-29 | AJ3: Mar-29 | AK3: Apr-29
A5: VARIABLE COSTS (scale with customer count)
A6: LLM API costs (Claude) | B6: =Revenue!B10*Assumptions!B29*Assumptions!B30*Assumptions!B60 -> 300 | C6: =Revenue!C10*Assumptions!B29*Assumptions!B30*Assumptions!B60 -> 300 | D6: =Revenue!D10*Assumptions!B29*Assumptions!B30*Assumptions!B60 -> 300 | E6: =Revenue!E10*Assumptions!B29*Assumptions!B30*Assumptions!B60 -> 300 | F6: =Revenue!F10*Assumptions!B29*Assumptions!B30*Assumptions!B60 -> 300 | G6: =Revenue!G10*Assumptions!B29*Assumptions!B30*Assumptions!B60 -> 600 | H6: =Revenue!H10*Assumptions!B29*Assumptions!B30*Assumptions!B60 -> 600 | I6: =Revenue!I10*Assumptions!B29*Assumptions!B30*Assumptions!B60 -> 600 | J6: =Revenue!J10*Assumptions!B29*Assumptions!B30*Assumptions!B60 -> 600 | K6: =Revenue!K10*Assumptions!B29*Assumptions!B30*Assumptions!B60 -> 600 | L6: =Revenue!L10*Assumptions!B29*Assumptions!B30*Assumptions!B60 -> 900 | M6: =Revenue!M10*Assumptions!B29*Assumptions!B30*Assumptions!B60 -> 900 | N6: =Revenue!N10*Assumptions!B29*Assumptions!B30*Assumptions!B60 -> 900 | O6: =Revenue!O10*Assumptions!B29*Assumptions!B30*Assumptions!B60 -> 1200 | P6: =Revenue!P10*Assumptions!B29*Assumptions!B30*Assumptions!B60 -> 1200 | Q6: =Revenue!Q10*Assumptions!B29*Assumptions!B30*Assumptions!B60 -> 1200 | R6: =Revenue!R10*Assumptions!B29*Assumptions!B30*Assumptions!B60 -> 1500 | S6: =Revenue!S10*Assumptions!B29*Assumptions!B30*Assumptions!B60 -> 1800 | T6: =Revenue!T10*Assumptions!B29*Assumptions!B30*Assumptions!B60 -> 1800 | U6: =Revenue!U10*Assumptions!B29*Assumptions!B30*Assumptions!B60 -> 2100 | V6: =Revenue!V10*Assumptions!B29*Assumptions!B30*Assumptions!B60 -> 2100 | W6: =Revenue!W10*Assumptions!B29*Assumptions!B30*Assumptions!B60 -> 2400 | X6: =Revenue!X10*Assumptions!B29*Assumptions!B30*Assumptions!B60 -> 2700 | Y6: =Revenue!Y10*Assumptions!B29*Assumptions!B30*Assumptions!B60 -> 2700 | Z6: =Revenue!Z10*Assumptions!B29*Assumptions!B30*Assumptions!B60 -> 3000 | AA6: =Revenue!AA10*Assumptions!B29*Assumptions!B30*Assumptions!B60 -> 3300 | AB6: =Revenue!AB10*Assumptions!B29*Assumptions!B30*Assumptions!B60 -> 3600 | AC6: =Revenue!AC10*Assumptions!B29*Assumptions!B30*Assumptions!B60 -> 4200 | AD6: =Revenue!AD10*Assumptions!B29*Assumptions!B30*Assumptions!B60 -> 4500 | AE6: =Revenue!AE10*Assumptions!B29*Assumptions!B30*Assumptions!B60 -> 4800 | AF6: =Revenue!AF10*Assumptions!B29*Assumptions!B30*Assumptions!B60 -> 5100 | AG6: =Revenue!AG10*Assumptions!B29*Assumptions!B30*Assumptions!B60 -> 5400 | AH6: =Revenue!AH10*Assumptions!B29*Assumptions!B30*Assumptions!B60 -> 5700 | AI6: =Revenue!AI10*Assumptions!B29*Assumptions!B30*Assumptions!B60 -> 6300 | AJ6: =Revenue!AJ10*Assumptions!B29*Assumptions!B30*Assumptions!B60 -> 6600 | AK6: =Revenue!AK10*Assumptions!B29*Assumptions!B30*Assumptions!B60 -> 6600 | AL6: =SUM(B6:M6) -> 6300 | AM6: =SUM(N6:Y6) -> 21600 | AN6: =SUM(Z6:AK6) -> 59100 | AO6: =AL6+AM6+AN6 -> 87000
A7: Hosting (Vercel + Neon + R2 + Inngest) | B7: =Revenue!B10*Assumptions!B31*Assumptions!B60 -> 50 | C7: =Revenue!C10*Assumptions!B31*Assumptions!B60 -> 50 | D7: =Revenue!D10*Assumptions!B31*Assumptions!B60 -> 50 | E7: =Revenue!E10*Assumptions!B31*Assumptions!B60 -> 50 | F7: =Revenue!F10*Assumptions!B31*Assumptions!B60 -> 50 | G7: =Revenue!G10*Assumptions!B31*Assumptions!B60 -> 100 | H7: =Revenue!H10*Assumptions!B31*Assumptions!B60 -> 100 | I7: =Revenue!I10*Assumptions!B31*Assumptions!B60 -> 100 | J7: =Revenue!J10*Assumptions!B31*Assumptions!B60 -> 100 | K7: =Revenue!K10*Assumptions!B31*Assumptions!B60 -> 100 | L7: =Revenue!L10*Assumptions!B31*Assumptions!B60 -> 150 | M7: =Revenue!M10*Assumptions!B31*Assumptions!B60 -> 150 | N7: =Revenue!N10*Assumptions!B31*Assumptions!B60 -> 150 | O7: =Revenue!O10*Assumptions!B31*Assumptions!B60 -> 200 | P7: =Revenue!P10*Assumptions!B31*Assumptions!B60 -> 200 | Q7: =Revenue!Q10*Assumptions!B31*Assumptions!B60 -> 200 | R7: =Revenue!R10*Assumptions!B31*Assumptions!B60 -> 250 | S7: =Revenue!S10*Assumptions!B31*Assumptions!B60 -> 300 | T7: =Revenue!T10*Assumptions!B31*Assumptions!B60 -> 300 | U7: =Revenue!U10*Assumptions!B31*Assumptions!B60 -> 350 | V7: =Revenue!V10*Assumptions!B31*Assumptions!B60 -> 350 | W7: =Revenue!W10*Assumptions!B31*Assumptions!B60 -> 400 | X7: =Revenue!X10*Assumptions!B31*Assumptions!B60 -> 450 | Y7: =Revenue!Y10*Assumptions!B31*Assumptions!B60 -> 450 | Z7: =Revenue!Z10*Assumptions!B31*Assumptions!B60 -> 500 | AA7: =Revenue!AA10*Assumptions!B31*Assumptions!B60 -> 550 | AB7: =Revenue!AB10*Assumptions!B31*Assumptions!B60 -> 600 | AC7: =Revenue!AC10*Assumptions!B31*Assumptions!B60 -> 700 | AD7: =Revenue!AD10*Assumptions!B31*Assumptions!B60 -> 750 | AE7: =Revenue!AE10*Assumptions!B31*Assumptions!B60 -> 800 | AF7: =Revenue!AF10*Assumptions!B31*Assumptions!B60 -> 850 | AG7: =Revenue!AG10*Assumptions!B31*Assumptions!B60 -> 900 | AH7: =Revenue!AH10*Assumptions!B31*Assumptions!B60 -> 950 | AI7: =Revenue!AI10*Assumptions!B31*Assumptions!B60 -> 1050 | AJ7: =Revenue!AJ10*Assumptions!B31*Assumptions!B60 -> 1100 | AK7: =Revenue!AK10*Assumptions!B31*Assumptions!B60 -> 1100 | AL7: =SUM(B7:M7) -> 1050 | AM7: =SUM(N7:Y7) -> 3600 | AN7: =SUM(Z7:AK7) -> 9850 | AO7: =AL7+AM7+AN7 -> 14500
A9: FIXED COSTS
A10: Tooling (Stripe, Clerk, Sentry, etc.) | B10: =Assumptions!B32*Assumptions!B60 -> 400 | C10: =Assumptions!B32*Assumptions!B60 -> 400 | D10: =Assumptions!B32*Assumptions!B60 -> 400 | E10: =Assumptions!B32*Assumptions!B60 -> 400 | F10: =Assumptions!B32*Assumptions!B60 -> 400 | G10: =Assumptions!B32*Assumptions!B60 -> 400 | H10: =Assumptions!B32*Assumptions!B60 -> 400 | I10: =Assumptions!B32*Assumptions!B60 -> 400 | J10: =Assumptions!B32*Assumptions!B60 -> 400 | K10: =Assumptions!B32*Assumptions!B60 -> 400 | L10: =Assumptions!B32*Assumptions!B60 -> 400 | M10: =Assumptions!B32*Assumptions!B60 -> 400 | N10: =Assumptions!B32*Assumptions!B60 -> 400 | O10: =Assumptions!B32*Assumptions!B60 -> 400 | P10: =Assumptions!B32*Assumptions!B60 -> 400 | Q10: =Assumptions!B32*Assumptions!B60 -> 400 | R10: =Assumptions!B32*Assumptions!B60 -> 400 | S10: =Assumptions!B32*Assumptions!B60 -> 400 | T10: =Assumptions!B32*Assumptions!B60 -> 400 | U10: =Assumptions!B32*Assumptions!B60 -> 400 | V10: =Assumptions!B32*Assumptions!B60 -> 400 | W10: =Assumptions!B32*Assumptions!B60 -> 400 | X10: =Assumptions!B32*Assumptions!B60 -> 400 | Y10: =Assumptions!B32*Assumptions!B60 -> 400 | Z10: =Assumptions!B32*Assumptions!B60 -> 400 | AA10: =Assumptions!B32*Assumptions!B60 -> 400 | AB10: =Assumptions!B32*Assumptions!B60 -> 400 | AC10: =Assumptions!B32*Assumptions!B60 -> 400 | AD10: =Assumptions!B32*Assumptions!B60 -> 400 | AE10: =Assumptions!B32*Assumptions!B60 -> 400 | AF10: =Assumptions!B32*Assumptions!B60 -> 400 | AG10: =Assumptions!B32*Assumptions!B60 -> 400 | AH10: =Assumptions!B32*Assumptions!B60 -> 400 | AI10: =Assumptions!B32*Assumptions!B60 -> 400 | AJ10: =Assumptions!B32*Assumptions!B60 -> 400 | AK10: =Assumptions!B32*Assumptions!B60 -> 400 | AL10: =SUM(B10:M10) -> 4800 | AM10: =SUM(N10:Y10) -> 4800 | AN10: =SUM(Z10:AK10) -> 4800 | AO10: =AL10+AM10+AN10 -> 14400
A11: Legal | B11: =Assumptions!B33/12*Assumptions!B60 -> 1250 | C11: =Assumptions!B33/12*Assumptions!B60 -> 1250 | D11: =Assumptions!B33/12*Assumptions!B60 -> 1250 | E11: =Assumptions!B33/12*Assumptions!B60 -> 1250 | F11: =Assumptions!B33/12*Assumptions!B60 -> 1250 | G11: =Assumptions!B33/12*Assumptions!B60 -> 1250 | H11: =Assumptions!B33/12*Assumptions!B60 -> 1250 | I11: =Assumptions!B33/12*Assumptions!B60 -> 1250 | J11: =Assumptions!B33/12*Assumptions!B60 -> 1250 | K11: =Assumptions!B33/12*Assumptions!B60 -> 1250 | L11: =Assumptions!B33/12*Assumptions!B60 -> 1250 | M11: =Assumptions!B33/12*Assumptions!B60 -> 1250 | N11: =Assumptions!B34/12*Assumptions!B60 -> 2083.3333 | O11: =Assumptions!B34/12*Assumptions!B60 -> 2083.3333 | P11: =Assumptions!B34/12*Assumptions!B60 -> 2083.3333 | Q11: =Assumptions!B34/12*Assumptions!B60 -> 2083.3333 | R11: =Assumptions!B34/12*Assumptions!B60 -> 2083.3333 | S11: =Assumptions!B34/12*Assumptions!B60 -> 2083.3333 | T11: =Assumptions!B34/12*Assumptions!B60 -> 2083.3333 | U11: =Assumptions!B34/12*Assumptions!B60 -> 2083.3333 | V11: =Assumptions!B34/12*Assumptions!B60 -> 2083.3333 | W11: =Assumptions!B34/12*Assumptions!B60 -> 2083.3333 | X11: =Assumptions!B34/12*Assumptions!B60 -> 2083.3333 | Y11: =Assumptions!B34/12*Assumptions!B60 -> 2083.3333 | Z11: =Assumptions!B35/12*Assumptions!B60 -> 3333.3333 | AA11: =Assumptions!B35/12*Assumptions!B60 -> 3333.3333 | AB11: =Assumptions!B35/12*Assumptions!B60 -> 3333.3333 | AC11: =Assumptions!B35/12*Assumptions!B60 -> 3333.3333 | AD11: =Assumptions!B35/12*Assumptions!B60 -> 3333.3333 | AE11: =Assumptions!B35/12*Assumptions!B60 -> 3333.3333 | AF11: =Assumptions!B35/12*Assumptions!B60 -> 3333.3333 | AG11: =Assumptions!B35/12*Assumptions!B60 -> 3333.3333 | AH11: =Assumptions!B35/12*Assumptions!B60 -> 3333.3333 | AI11: =Assumptions!B35/12*Assumptions!B60 -> 3333.3333 | AJ11: =Assumptions!B35/12*Assumptions!B60 -> 3333.3333 | AK11: =Assumptions!B35/12*Assumptions!B60 -> 3333.3333 | AL11: =SUM(B11:M11) -> 15000 | AM11: =SUM(N11:Y11) -> 25000 | AN11: =SUM(Z11:AK11) -> 40000 | AO11: =AL11+AM11+AN11 -> 80000
A12: Accounting/tax | B12: =Assumptions!B36/12*Assumptions!B60 -> 500 | C12: =Assumptions!B36/12*Assumptions!B60 -> 500 | D12: =Assumptions!B36/12*Assumptions!B60 -> 500 | E12: =Assumptions!B36/12*Assumptions!B60 -> 500 | F12: =Assumptions!B36/12*Assumptions!B60 -> 500 | G12: =Assumptions!B36/12*Assumptions!B60 -> 500 | H12: =Assumptions!B36/12*Assumptions!B60 -> 500 | I12: =Assumptions!B36/12*Assumptions!B60 -> 500 | J12: =Assumptions!B36/12*Assumptions!B60 -> 500 | K12: =Assumptions!B36/12*Assumptions!B60 -> 500 | L12: =Assumptions!B36/12*Assumptions!B60 -> 500 | M12: =Assumptions!B36/12*Assumptions!B60 -> 500 | N12: =Assumptions!B36/12*Assumptions!B60 -> 500 | O12: =Assumptions!B36/12*Assumptions!B60 -> 500 | P12: =Assumptions!B36/12*Assumptions!B60 -> 500 | Q12: =Assumptions!B36/12*Assumptions!B60 -> 500 | R12: =Assumptions!B36/12*Assumptions!B60 -> 500 | S12: =Assumptions!B36/12*Assumptions!B60 -> 500 | T12: =Assumptions!B36/12*Assumptions!B60 -> 500 | U12: =Assumptions!B36/12*Assumptions!B60 -> 500 | V12: =Assumptions!B36/12*Assumptions!B60 -> 500 | W12: =Assumptions!B36/12*Assumptions!B60 -> 500 | X12: =Assumptions!B36/12*Assumptions!B60 -> 500 | Y12: =Assumptions!B36/12*Assumptions!B60 -> 500 | Z12: =Assumptions!B36/12*Assumptions!B60 -> 500 | AA12: =Assumptions!B36/12*Assumptions!B60 -> 500 | AB12: =Assumptions!B36/12*Assumptions!B60 -> 500 | AC12: =Assumptions!B36/12*Assumptions!B60 -> 500 | AD12: =Assumptions!B36/12*Assumptions!B60 -> 500 | AE12: =Assumptions!B36/12*Assumptions!B60 -> 500 | AF12: =Assumptions!B36/12*Assumptions!B60 -> 500 | AG12: =Assumptions!B36/12*Assumptions!B60 -> 500 | AH12: =Assumptions!B36/12*Assumptions!B60 -> 500 | AI12: =Assumptions!B36/12*Assumptions!B60 -> 500 | AJ12: =Assumptions!B36/12*Assumptions!B60 -> 500 | AK12: =Assumptions!B36/12*Assumptions!B60 -> 500 | AL12: =SUM(B12:M12) -> 6000 | AM12: =SUM(N12:Y12) -> 6000 | AN12: =SUM(Z12:AK12) -> 6000 | AO12: =AL12+AM12+AN12 -> 18000
A13: Marketing | B13: =Assumptions!B37/12*Assumptions!B60 -> 416.66667 | C13: =Assumptions!B37/12*Assumptions!B60 -> 416.66667 | D13: =Assumptions!B37/12*Assumptions!B60 -> 416.66667 | E13: =Assumptions!B37/12*Assumptions!B60 -> 416.66667 | F13: =Assumptions!B37/12*Assumptions!B60 -> 416.66667 | G13: =Assumptions!B37/12*Assumptions!B60 -> 416.66667 | H13: =Assumptions!B37/12*Assumptions!B60 -> 416.66667 | I13: =Assumptions!B37/12*Assumptions!B60 -> 416.66667 | J13: =Assumptions!B37/12*Assumptions!B60 -> 416.66667 | K13: =Assumptions!B37/12*Assumptions!B60 -> 416.66667 | L13: =Assumptions!B37/12*Assumptions!B60 -> 416.66667 | M13: =Assumptions!B37/12*Assumptions!B60 -> 416.66667 | N13: =Assumptions!B38/12*Assumptions!B60 -> 2500 | O13: =Assumptions!B38/12*Assumptions!B60 -> 2500 | P13: =Assumptions!B38/12*Assumptions!B60 -> 2500 | Q13: =Assumptions!B38/12*Assumptions!B60 -> 2500 | R13: =Assumptions!B38/12*Assumptions!B60 -> 2500 | S13: =Assumptions!B38/12*Assumptions!B60 -> 2500 | T13: =Assumptions!B38/12*Assumptions!B60 -> 2500 | U13: =Assumptions!B38/12*Assumptions!B60 -> 2500 | V13: =Assumptions!B38/12*Assumptions!B60 -> 2500 | W13: =Assumptions!B38/12*Assumptions!B60 -> 2500 | X13: =Assumptions!B38/12*Assumptions!B60 -> 2500 | Y13: =Assumptions!B38/12*Assumptions!B60 -> 2500 | Z13: =Assumptions!B39/12*Assumptions!B60 -> 12500 | AA13: =Assumptions!B39/12*Assumptions!B60 -> 12500 | AB13: =Assumptions!B39/12*Assumptions!B60 -> 12500 | AC13: =Assumptions!B39/12*Assumptions!B60 -> 12500 | AD13: =Assumptions!B39/12*Assumptions!B60 -> 12500 | AE13: =Assumptions!B39/12*Assumptions!B60 -> 12500 | AF13: =Assumptions!B39/12*Assumptions!B60 -> 12500 | AG13: =Assumptions!B39/12*Assumptions!B60 -> 12500 | AH13: =Assumptions!B39/12*Assumptions!B60 -> 12500 | AI13: =Assumptions!B39/12*Assumptions!B60 -> 12500 | AJ13: =Assumptions!B39/12*Assumptions!B60 -> 12500 | AK13: =Assumptions!B39/12*Assumptions!B60 -> 12500 | AL13: =SUM(B13:M13) -> 5000 | AM13: =SUM(N13:Y13) -> 30000 | AN13: =SUM(Z13:AK13) -> 150000 | AO13: =AL13+AM13+AN13 -> 185000
A15: PEOPLE COSTS
A16: Engineer contractor (Y2+) | B16: 0 | C16: 0 | D16: 0 | E16: 0 | F16: 0 | G16: 0 | H16: 0 | I16: 0 | J16: 0 | K16: 0 | L16: 0 | M16: 0 | N16: =Assumptions!B40*Assumptions!B60 -> 8000 | O16: =Assumptions!B40*Assumptions!B60 -> 8000 | P16: =Assumptions!B40*Assumptions!B60 -> 8000 | Q16: =Assumptions!B40*Assumptions!B60 -> 8000 | R16: =Assumptions!B40*Assumptions!B60 -> 8000 | S16: =Assumptions!B40*Assumptions!B60 -> 8000 | T16: =Assumptions!B40*Assumptions!B60 -> 8000 | U16: =Assumptions!B40*Assumptions!B60 -> 8000 | V16: =Assumptions!B40*Assumptions!B60 -> 8000 | W16: =Assumptions!B40*Assumptions!B60 -> 8000 | X16: =Assumptions!B40*Assumptions!B60 -> 8000 | Y16: =Assumptions!B40*Assumptions!B60 -> 8000 | Z16: =Assumptions!B40*Assumptions!B60 -> 8000 | AA16: =Assumptions!B40*Assumptions!B60 -> 8000 | AB16: =Assumptions!B40*Assumptions!B60 -> 8000 | AC16: =Assumptions!B40*Assumptions!B60 -> 8000 | AD16: =Assumptions!B40*Assumptions!B60 -> 8000 | AE16: =Assumptions!B40*Assumptions!B60 -> 8000 | AF16: =Assumptions!B40*Assumptions!B60 -> 8000 | AG16: =Assumptions!B40*Assumptions!B60 -> 8000 | AH16: =Assumptions!B40*Assumptions!B60 -> 8000 | AI16: =Assumptions!B40*Assumptions!B60 -> 8000 | AJ16: =Assumptions!B40*Assumptions!B60 -> 8000 | AK16: =Assumptions!B40*Assumptions!B60 -> 8000 | AL16: =SUM(B16:M16) -> 0 | AM16: =SUM(N16:Y16) -> 96000 | AN16: =SUM(Z16:AK16) -> 96000 | AO16: =AL16+AM16+AN16 -> 192000
A17: Curator contractor (Y2+) | B17: 0 | C17: 0 | D17: 0 | E17: 0 | F17: 0 | G17: 0 | H17: 0 | I17: 0 | J17: 0 | K17: 0 | L17: 0 | M17: 0 | N17: 0 | O17: 0 | P17: =Assumptions!B41*Assumptions!B60 -> 4000 | Q17: =Assumptions!B41*Assumptions!B60 -> 4000 | R17: =Assumptions!B41*Assumptions!B60 -> 4000 | S17: =Assumptions!B41*Assumptions!B60 -> 4000 | T17: =Assumptions!B41*Assumptions!B60 -> 4000 | U17: =Assumptions!B41*Assumptions!B60 -> 4000 | V17: =Assumptions!B41*Assumptions!B60 -> 4000 | W17: =Assumptions!B41*Assumptions!B60 -> 4000 | X17: =Assumptions!B41*Assumptions!B60 -> 4000 | Y17: =Assumptions!B41*Assumptions!B60 -> 4000 | Z17: =Assumptions!B41*Assumptions!B60 -> 4000 | AA17: =Assumptions!B41*Assumptions!B60 -> 4000 | AB17: =Assumptions!B41*Assumptions!B60 -> 4000 | AC17: =Assumptions!B41*Assumptions!B60 -> 4000 | AD17: =Assumptions!B41*Assumptions!B60 -> 4000 | AE17: =Assumptions!B41*Assumptions!B60 -> 4000 | AF17: =Assumptions!B41*Assumptions!B60 -> 4000 | AG17: =Assumptions!B41*Assumptions!B60 -> 4000 | AH17: =Assumptions!B41*Assumptions!B60 -> 4000 | AI17: =Assumptions!B41*Assumptions!B60 -> 4000 | AJ17: =Assumptions!B41*Assumptions!B60 -> 4000 | AK17: =Assumptions!B41*Assumptions!B60 -> 4000 | AL17: =SUM(B17:M17) -> 0 | AM17: =SUM(N17:Y17) -> 40000 | AN17: =SUM(Z17:AK17) -> 48000 | AO17: =AL17+AM17+AN17 -> 88000
A18: FTE engineer (Y3) | B18: 0 | C18: 0 | D18: 0 | E18: 0 | F18: 0 | G18: 0 | H18: 0 | I18: 0 | J18: 0 | K18: 0 | L18: 0 | M18: 0 | N18: 0 | O18: 0 | P18: 0 | Q18: 0 | R18: 0 | S18: 0 | T18: 0 | U18: 0 | V18: 0 | W18: 0 | X18: 0 | Y18: 0 | Z18: =Assumptions!B42*Assumptions!B60 -> 12500 | AA18: =Assumptions!B42*Assumptions!B60 -> 12500 | AB18: =Assumptions!B42*Assumptions!B60 -> 12500 | AC18: =Assumptions!B42*Assumptions!B60 -> 12500 | AD18: =Assumptions!B42*Assumptions!B60 -> 12500 | AE18: =Assumptions!B42*Assumptions!B60 -> 12500 | AF18: =Assumptions!B42*Assumptions!B60 -> 12500 | AG18: =Assumptions!B42*Assumptions!B60 -> 12500 | AH18: =Assumptions!B42*Assumptions!B60 -> 12500 | AI18: =Assumptions!B42*Assumptions!B60 -> 12500 | AJ18: =Assumptions!B42*Assumptions!B60 -> 12500 | AK18: =Assumptions!B42*Assumptions!B60 -> 12500 | AL18: =SUM(B18:M18) -> 0 | AM18: =SUM(N18:Y18) -> 0 | AN18: =SUM(Z18:AK18) -> 150000 | AO18: =AL18+AM18+AN18 -> 150000
A19: FTE pack-authoring lead (Y3) | B19: 0 | C19: 0 | D19: 0 | E19: 0 | F19: 0 | G19: 0 | H19: 0 | I19: 0 | J19: 0 | K19: 0 | L19: 0 | M19: 0 | N19: 0 | O19: 0 | P19: 0 | Q19: 0 | R19: 0 | S19: 0 | T19: 0 | U19: 0 | V19: 0 | W19: 0 | X19: 0 | Y19: 0 | Z19: 0 | AA19: 0 | AB19: 0 | AC19: =Assumptions!B43*Assumptions!B60 -> 10000 | AD19: =Assumptions!B43*Assumptions!B60 -> 10000 | AE19: =Assumptions!B43*Assumptions!B60 -> 10000 | AF19: =Assumptions!B43*Assumptions!B60 -> 10000 | AG19: =Assumptions!B43*Assumptions!B60 -> 10000 | AH19: =Assumptions!B43*Assumptions!B60 -> 10000 | AI19: =Assumptions!B43*Assumptions!B60 -> 10000 | AJ19: =Assumptions!B43*Assumptions!B60 -> 10000 | AK19: =Assumptions!B43*Assumptions!B60 -> 10000 | AL19: =SUM(B19:M19) -> 0 | AM19: =SUM(N19:Y19) -> 0 | AN19: =SUM(Z19:AK19) -> 90000 | AO19: =AL19+AM19+AN19 -> 90000
A20: FTE customer success (Y3) | B20: 0 | C20: 0 | D20: 0 | E20: 0 | F20: 0 | G20: 0 | H20: 0 | I20: 0 | J20: 0 | K20: 0 | L20: 0 | M20: 0 | N20: 0 | O20: 0 | P20: 0 | Q20: 0 | R20: 0 | S20: 0 | T20: 0 | U20: 0 | V20: 0 | W20: 0 | X20: 0 | Y20: 0 | Z20: 0 | AA20: 0 | AB20: 0 | AC20: 0 | AD20: 0 | AE20: 0 | AF20: =Assumptions!B44*Assumptions!B60 -> 8500 | AG20: =Assumptions!B44*Assumptions!B60 -> 8500 | AH20: =Assumptions!B44*Assumptions!B60 -> 8500 | AI20: =Assumptions!B44*Assumptions!B60 -> 8500 | AJ20: =Assumptions!B44*Assumptions!B60 -> 8500 | AK20: =Assumptions!B44*Assumptions!B60 -> 8500 | AL20: =SUM(B20:M20) -> 0 | AM20: =SUM(N20:Y20) -> 0 | AN20: =SUM(Z20:AK20) -> 51000 | AO20: =AL20+AM20+AN20 -> 51000
A21: Shalom compensation (allocated) | B21: =Assumptions!B45/12*Assumptions!B60 -> 2916.6667 | C21: =Assumptions!B45/12*Assumptions!B60 -> 2916.6667 | D21: =Assumptions!B45/12*Assumptions!B60 -> 2916.6667 | E21: =Assumptions!B45/12*Assumptions!B60 -> 2916.6667 | F21: =Assumptions!B45/12*Assumptions!B60 -> 2916.6667 | G21: =Assumptions!B45/12*Assumptions!B60 -> 2916.6667 | H21: =Assumptions!B45/12*Assumptions!B60 -> 2916.6667 | I21: =Assumptions!B45/12*Assumptions!B60 -> 2916.6667 | J21: =Assumptions!B45/12*Assumptions!B60 -> 2916.6667 | K21: =Assumptions!B45/12*Assumptions!B60 -> 2916.6667 | L21: =Assumptions!B45/12*Assumptions!B60 -> 2916.6667 | M21: =Assumptions!B45/12*Assumptions!B60 -> 2916.6667 | N21: =Assumptions!B46/12*Assumptions!B60 -> 8333.3333 | O21: =Assumptions!B46/12*Assumptions!B60 -> 8333.3333 | P21: =Assumptions!B46/12*Assumptions!B60 -> 8333.3333 | Q21: =Assumptions!B46/12*Assumptions!B60 -> 8333.3333 | R21: =Assumptions!B46/12*Assumptions!B60 -> 8333.3333 | S21: =Assumptions!B46/12*Assumptions!B60 -> 8333.3333 | T21: =Assumptions!B46/12*Assumptions!B60 -> 8333.3333 | U21: =Assumptions!B46/12*Assumptions!B60 -> 8333.3333 | V21: =Assumptions!B46/12*Assumptions!B60 -> 8333.3333 | W21: =Assumptions!B46/12*Assumptions!B60 -> 8333.3333 | X21: =Assumptions!B46/12*Assumptions!B60 -> 8333.3333 | Y21: =Assumptions!B46/12*Assumptions!B60 -> 8333.3333 | Z21: =Assumptions!B47/12*Assumptions!B60 -> 16666.667 | AA21: =Assumptions!B47/12*Assumptions!B60 -> 16666.667 | AB21: =Assumptions!B47/12*Assumptions!B60 -> 16666.667 | AC21: =Assumptions!B47/12*Assumptions!B60 -> 16666.667 | AD21: =Assumptions!B47/12*Assumptions!B60 -> 16666.667 | AE21: =Assumptions!B47/12*Assumptions!B60 -> 16666.667 | AF21: =Assumptions!B47/12*Assumptions!B60 -> 16666.667 | AG21: =Assumptions!B47/12*Assumptions!B60 -> 16666.667 | AH21: =Assumptions!B47/12*Assumptions!B60 -> 16666.667 | AI21: =Assumptions!B47/12*Assumptions!B60 -> 16666.667 | AJ21: =Assumptions!B47/12*Assumptions!B60 -> 16666.667 | AK21: =Assumptions!B47/12*Assumptions!B60 -> 16666.667 | AL21: =SUM(B21:M21) -> 35000 | AM21: =SUM(N21:Y21) -> 100000 | AN21: =SUM(Z21:AK21) -> 200000 | AO21: =AL21+AM21+AN21 -> 335000
A23: TOTAL MONTHLY COSTS | B23: =SUM(B6:B21) -> 5833.3333 | C23: =SUM(C6:C21) -> 5833.3333 | D23: =SUM(D6:D21) -> 5833.3333 | E23: =SUM(E6:E21) -> 5833.3333 | F23: =SUM(F6:F21) -> 5833.3333 | G23: =SUM(G6:G21) -> 6183.3333 | H23: =SUM(H6:H21) -> 6183.3333 | I23: =SUM(I6:I21) -> 6183.3333 | ... AK23: =SUM(AK6:AK21) -> 84100 | AL23: =SUM(B23:M23) -> 73150 | AM23: =SUM(N23:Y23) -> 327000 | AN23: =SUM(Z23:AK23) -> 904750 | AO23: =AL23+AM23+AN23 -> 1304900

Sheet P&L
A1: Signal Array — Monthly P&L and Cash Position
B2: Year 1 (May26-Apr27) | N2: Year 2 (May27-Apr28) | Z2: Year 3 (May28-Apr29) | AL2: Y1 Total | AM2: Y2 Total | AN2: Y3 Total | AO2: 3Y Total
A3: Month | B3: May-26 | C3: Jun-26 | D3: Jul-26 | E3: Aug-26 | F3: Sep-26 | G3: Oct-26 | H3: Nov-26 | I3: Dec-26 | J3: Jan-27 | K3: Feb-27 | L3: Mar-27 | M3: Apr-27 | N3: May-27 | O3: Jun-27 | P3: Jul-27 | Q3: Aug-27 | R3: Sep-27 | S3: Oct-27 | T3: Nov-27 | U3: Dec-27 | V3: Jan-28 | W3: Feb-28 | X3: Mar-28 | Y3: Apr-28 | Z3: May-28 | AA3: Jun-28 | AB3: Jul-28 | AC3: Aug-28 | AD3: Sep-28 | AE3: Oct-28 | AF3: Nov-28 | AG3: Dec-28 | AH3: Jan-29 | AI3: Feb-29 | AJ3: Mar-29 | AK3: Apr-29
A5: Revenue | B5: =Revenue!B19 -> 12500 | C5: =Revenue!C19 -> 12500 | D5: =Revenue!D19 -> 12500 | E5: =Revenue!E19 -> 12500 | F5: =Revenue!F19 -> 12500 | G5: =Revenue!G19 -> 43750 | H5: =Revenue!H19 -> 13750 | I5: =Revenue!I19 -> 13750 | ... AK5: =Revenue!AK19 -> 120416.67 | AL5: =SUM(B5:M5) -> 221250 | AM5: =SUM(N5:Y5) -> 577500 | AN5: =SUM(Z5:AK5) -> 1552916.7 | AO5: =AL5+AM5+AN5 -> 2351666.7
A6: Total costs | B6: =Costs!B23 -> 5833.3333 | C6: =Costs!C23 -> 5833.3333 | D6: =Costs!D23 -> 5833.3333 | E6: =Costs!E23 -> 5833.3333 | F6: =Costs!F23 -> 5833.3333 | G6: =Costs!G23 -> 6183.3333 | H6: =Costs!H23 -> 6183.3333 | I6: =Costs!I23 -> 6183.3333 | ... AK6: =Costs!AK23 -> 84100 | AL6: =SUM(B6:M6) -> 73150 | AM6: =SUM(N6:Y6) -> 327000 | AN6: =SUM(Z6:AK6) -> 904750 | AO6: =AL6+AM6+AN6 -> 1304900
A7: Net contribution | B7: =B5-B6 -> 6666.6667 | C7: =C5-C6 -> 6666.6667 | D7: =D5-D6 -> 6666.6667 | E7: =E5-E6 -> 6666.6667 | F7: =F5-F6 -> 6666.6667 | G7: =G5-G6 -> 37566.667 | H7: =H5-H6 -> 7566.6667 | I7: =I5-I6 -> 7566.6667 | ... AK7: =AK5-AK6 -> 36316.667 | AL7: =SUM(B7:M7) -> 148100 | AM7: =SUM(N7:Y7) -> 250500 | AN7: =SUM(Z7:AK7) -> 648166.67 | AO7: =AL7+AM7+AN7 -> 1046766.7
A9: Cumulative net cash position | B9: =B7 -> 6666.6667 | C9: =B9+C7 -> 13333.333 | D9: =C9+D7 -> 20000 | E9: =D9+E7 -> 26666.667 | F9: =E9+F7 -> 33333.333 | G9: =F9+G7 -> 70900 | H9: =G9+H7 -> 78466.667 | I9: =H9+I7 -> 86033.333 | J9: =I9+J7 -> 93600 | ... AK9: =AJ9+AK7 -> 1046766.7 | AL9: =M9 -> 148100 | AM9: =Y9 -> 398600 | AN9: =AK9 -> 1046766.7 | AO9: =AK9 -> 1046766.7
A11: Variable cost (LLM + hosting) | B11: =Costs!B6+Costs!B7 -> 350 | C11: =Costs!C6+Costs!C7 -> 350 | D11: =Costs!D6+Costs!D7 -> 350 | E11: =Costs!E6+Costs!E7 -> 350 | F11: =Costs!F6+Costs!F7 -> 350 | G11: =Costs!G6+Costs!G7 -> 700 | H11: =Costs!H6+Costs!H7 -> 700 | I11: =Costs!I6+Costs!I7 -> 700 | ... AK11: =Costs!AK6+Costs!AK7 -> 7700 | AL11: =SUM(B11:M11) -> 7350 | AM11: =SUM(N11:Y11) -> 25200 | AN11: =SUM(Z11:AK11) -> 68950 | AO11: =AL11+AM11+AN11 -> 101500
A12: Gross margin % | B12: =IFERROR((B5-B11)/B5,0) -> 0.972 | C12: =IFERROR((C5-C11)/C5,0) -> 0.972 | D12: =IFERROR((D5-D11)/D5,0) -> 0.972 | E12: =IFERROR((E5-E11)/E5,0) -> 0.972 | F12: =IFERROR((F5-F11)/F5,0) -> 0.972 | G12: =IFERROR((G5-G11)/G5,0) -> 0.984 | H12: =IFERROR((H5-H11)/H5,0) -> 0.94909091 | I12: =IFERROR((I5-I11)/I5,0) -> 0.94909091 | ... AK12: =IFERROR((AK5-AK11)/AK5,0) -> 0.93605536 | AL12: =IFERROR(AVERAGE(B12:M12),0) -> 0.96225253 | AM12: =IFERROR(AVERAGE(N12:Y12),0) -> 0.94871089 | AN12: =IFERROR(AVERAGE(Z12:AK12),0) -> 0.95543776 | AO12: =AVERAGE(B12:AK12) -> 0.95546706

Sheet Unit Economics
A1: Signal Array — Unit Economics by Tier
A3: Metric | B3: Pilot Pack | C3: Platform Tier | D3: Enterprise
A4: Annual contract value (ACV) Y1 | B4: =Assumptions!B8+Assumptions!B7 -> 45000 | C4: =Assumptions!B10+Assumptions!B11 -> 100000 | D4: =Assumptions!B12 -> 250000
A5: Annual contract value (ACV) Y2+ | B5: =Assumptions!B9 -> 25000 | C5: =Assumptions!B10 -> 40000 | D5: =Assumptions!B12 -> 250000
A6: LLM cost/customer/year | B6: =Assumptions!B29*Assumptions!B30*12 -> 3600 | C6: =Assumptions!B29*Assumptions!B30*12*2 -> 7200 | D6: =Assumptions!B29*Assumptions!B30*12*4 -> 14400
A7: Hosting cost/customer/year | B7: =Assumptions!B31*12 -> 600 | C7: =Assumptions!B31*12*2 -> 1200 | D7: =Assumptions!B31*12*4 -> 2400
A8: Variable cost of delivery (total) | B8: =B6+B7 -> 4200 | C8: =C6+C7 -> 8400 | D8: =D6+D7 -> 16800
A9: Gross margin Y2+ | B9: =(B5-B8)/B5 -> 0.832 | C9: =(C5-C8)/C5 -> 0.79 | D9: =(D5-D8)/D5 -> 0.9328
A10: Estimated CAC (Y2 base) | B10: 5000 | C10: 20000 | D10: 50000
A11: Payback period (months) | B11: =B10/((B5/12)*B9) -> 2.8846154 | C11: =C10/((C5/12)*C9) -> 7.5949367 | D11: =D10/((D5/12)*D9) -> 2.5728988
A12: Estimated retention (years) | B12: 2.5 | C12: 4 | D12: 5
A13: LTV (ACV × retention × gross margin) | B13: =B5*B12*B9 -> 52000 | C13: =C5*C12*C9 -> 126400 | D13: =D5*D12*D9 -> 1166000
A14: LTV / CAC ratio | B14: =B13/B10 -> 10.4 | C14: =C13/C10 -> 6.32 | D14: =D13/D10 -> 23.32
A16: Notes
A17: • Pilot Pack Y1 ACV includes both the one-time pack-authoring fee and the first year of hosting.
A18: • Platform Y1 ACV includes both license and pack-authoring; Y2+ shows recurring license only.
A19: • Variable cost scales with cohort runs; Platform assumes 2x usage of Pilot; Enterprise 4x.
A20: • CAC includes attributed marketing + sales time. Pilot CAC is lower (warm intros, content-driven).
A21: • Retention assumes the calibration discipline holds; downside scenario cuts retention by ~40%.
A22: • LTV/CAC > 3x is healthy SaaS; Signal Array shows multiples of that across tiers in the base case.

Sheet KPI Dashboard
A1: Signal Array — Headline KPI Dashboard
A2: Reflects active scenario (see Assumptions sheet)
A4: Metric | B4: Year 1 | C4: Year 2 | D4: Year 3 | E4: 3Y Total/Avg
A5: Revenue (recognized) | B5: =Revenue!AL19 -> 221250 | C5: =Revenue!AM19 -> 577500 | D5: =Revenue!AN19 -> 1552916.7 | E5: =Revenue!AO19 -> 2351666.7
A6: Total costs | B6: =Costs!AL23 -> 73150 | C6: =Costs!AM23 -> 327000 | D6: =Costs!AN23 -> 904750 | E6: =Costs!AO23 -> 1304900
A7: Net contribution | B7: =B5-B6 -> 148100 | C7: =C5-C6 -> 250500 | D7: =D5-D6 -> 648166.67 | E7: =E5-E6 -> 1046766.7
A8: Net margin % | B8: =B7/B5 -> 0.66937853 | C8: =C7/C5 -> 0.43376623 | D8: =D7/D5 -> 0.41738664 | E8: =E7/E5 -> 0.44511694
A9: Customers (end of year) | B9: =Revenue!M10 -> 3 | C9: =Revenue!Y10 -> 9 | D9: =Revenue!AK10 -> 22 | E9: =D9 -> 22
A10: Variable costs (LLM + hosting) | B10: =Costs!AL6+Costs!AL7 -> 7350 | C10: =Costs!AM6+Costs!AM7 -> 25200 | D10: =Costs!AN6+Costs!AN7 -> 68950 | E10: =B10+C10+D10 -> 101500
A11: Marketing spend | B11: =Costs!AL13 -> 5000 | C11: =Costs!AM13 -> 30000 | D11: =Costs!AN13 -> 150000 | E11: =B11+C11+D11 -> 185000
A12: People costs total | B12: =Costs!AL16+Costs!AL17+Costs!AL18+Costs!AL19+Costs!AL20+Costs!AL21 -> 35000 | C12: =Costs!AM16+Costs!AM17+Costs!AM18+Costs!AM19+Costs!AM20+Costs!AM21 -> 236000 | D12: =Costs!AN16+Costs!AN17+Costs!AN18+Costs!AN19+Costs!AN20+Costs!AN21 -> 635000 | E12: =B12+C12+D12 -> 906000
A13: Avg gross margin % | B13: ='P&L'!AL12 -> 0.96225253 | C13: ='P&L'!AM12 -> 0.94871089 | D13: ='P&L'!AN12 -> 0.95543776 | E13: ='P&L'!AO12 -> 0.95546706
A14: Cumulative cash (EOY) | B14: ='P&L'!AL9 -> 148100 | C14: ='P&L'!AM9 -> 398600 | D14: ='P&L'!AN9 -> 1046766.7 | E14: ='P&L'!AO9 -> 1046766.7
A17: Read this scenario
A18: • Base case (Assumptions B61 = 1): Moloco lighthouse + steady pack acquisition. Healthy gross margins. Year 1 sustains operation; Year 2 funds first contractor; Year 3 supports small team.
A19: • Conservative case (set to 2): -33% revenue, slightly lower costs. Year 3 still positive; growth tempo slower.
A20: • Optimistic case (set to 3): +30% revenue with slightly higher costs. Year 3 ARR ~$2.5M; raise-vs-bootstrap decision is real.
A21: • Downside case (set to 4): -70% revenue; Moloco scaled back. Pivot to boutique consultancy posture; artifacts (paper, free demo) are career-grade outputs.

Sheet Sensitivity
A1: Signal Array — Sensitivity Analysis
A2: Year 2 Net Contribution by LLM cost / customer count combinations (base scenario)
A4: LLM cost per run → | B4: 5 | C4: 8 | D4: 10 | E4: 12 | F4: 15 | G4: 20
A5: 3 | B5: 176000 | C5: 170600 | D5: 167000 | E5: 163400 | F5: 158000 | G5: 149000
A6: 5 | B6: 262400 | C6: 254840 | D6: 249800 | E6: 244760 | F6: 237200 | G6: 224600
A7: 7 | B7: 348800 | C7: 339080 | D7: 332600 | E7: 326120 | F7: 316400 | G7: 300200
A8: 9 | B8: 435200 | C8: 423320 | D8: 415400 | E8: 407480 | F8: 395600 | G8: 375800
A9: 12 | B9: 564800 | C9: 549680 | D9: 539600 | E9: 529520 | F9: 514400 | G9: 489200
A10: 15 | B10: 694400 | C10: 676040 | D10: 663800 | E10: 651560 | F10: 633200 | G10: 602600
A14: Reading the table
A15: • Green = healthy Y2 net contribution; Red = problematic Y2 economics.
A16: • At base case (Y2 = 7 customers, $10/run LLM cost), Y2 net contribution is robust.
A17: • Sensitivity to LLM cost is real but bounded — even at $20/run, model holds at 9+ customers.
A18: • Sensitivity to customer count is the dominant risk — below 5 paying customers in Y2, model gets tight.
A19: • Mitigations: Claude prompt caching can reduce per-run cost 30–50%.
A20: • Mitigations: Creative Portfolios public demo drives Pilot inbound and reduces CAC pressure.
